<?xml version="1.0" encoding="utf-8"?>

<robot name="bruce_description">

  <mujoco>
      <compiler 
      meshdir="../meshes/" 
      balanceinertia="true" 
      discardvisual="false" />
  </mujoco>

  <link name="base_link">
    <inertial>
      <origin xyz="0.002673 -0.000683 0.077608" rpy="0 0 0" />
      <mass value="26" />
      <inertia ixx="0.22799" ixy="-0.00044" ixz="0.00273" iyy="0.99014" iyz="-0.00026" izz="1.11139" />
    </inertial>
    <visual>
      <origin xyz="0 0 0" rpy="0 0 0" />
      <geometry>
        <mesh filename="package://bruce_description/meshes/base_link.STL" />
      </geometry>
      <material name="">
        <color rgba="0.75294 0.75294 0.75294 1" />
      </material>
    </visual>
    <collision>
      <origin xyz="0 0 0.09" rpy="0 0 0" />
      <geometry>
        <box size="0.5 0.35 0.18"/>
      </geometry>
    </collision>
    <collision>
      <origin xyz="0.36 0 0.09" rpy="0 -0.45 0" />
      <geometry>
        <box size="0.15 0.03 0.14"/>
      </geometry>
    </collision>
    <collision>
      <origin xyz="-0.36 0 0.09" rpy="0 0.45 0" />
      <geometry>
        <box size="0.15 0.03 0.14"/>
      </geometry>
    </collision>
  </link>
  <link name="FL_hip">
    <inertial>
      <origin xyz="-0.00576 -0.01672 0" rpy="0 0 0" />
      <mass value="2.9" />
      <inertia ixx="0.00496" ixy="-0.00034" ixz="0.00000" iyy="0.00840" iyz="0.00001" izz="0.00686" />
    </inertial>
    <visual>
      <origin xyz="0 0 0" rpy="0 0 0" />
      <geometry>
        <mesh filename="package://bruce_description/meshes/FL_hip.STL" />
      </geometry>
      <material name="">
        <color rgba="0.75294 0.75294 0.75294 1" />
      </material>
    </visual>
    <collision>
      <origin xyz="0 -0.024 0" rpy="1.57 0 0" />
      <geometry>
        <cylinder radius="0.065" length="0.07 "/>
      </geometry>
    </collision>
  </link>
  <joint name="FL_hip_joint" type="revolute">
    <origin xyz="0.34075 0.0975 0.088" rpy="0 0 0" />
    <parent link="base_link" />
    <child link="FL_hip" />
    <axis xyz="1 0 0" />
    <limit lower="-0.75" upper="0.75" effort="200" velocity="5" />
  </joint>
  <link name="FL_thigh">
    <inertial>
      <origin xyz="-0.00465 -0.05050 -0.03161" rpy="0 0 0" />
      <mass value="5.58" />
      <inertia ixx="0.05229" ixy="0.00049" ixz="0.00270" iyy="0.04971" iyz="0.00720" izz="0.01637" />
    </inertial>
    <visual>
      <origin xyz="0 0 0" rpy="0 0 0" /> 
      <geometry>
        <mesh filename="package://bruce_description/meshes/FL_thigh.STL" />
      </geometry>
      <material name="">
        <color rgba="0.75294 0.75294 0.75294 1" />
      </material>
    </visual>
    <collision>
      <origin xyz="0 -0.045 0" rpy="1.57 0 0" />
      <geometry>
        <cylinder radius="0.07" length="0.14 "/>
      </geometry>
    </collision>
    <collision>
      <origin xyz="-0.0 0 -0.12" rpy="0 0.3 0" />
      <geometry>
        <box size="0.065 0.045 0.22"/>
      </geometry>
    </collision>
    <collision>
      <origin xyz="-0.05 0 -0.12" rpy="0 0 0" />
      <geometry>
        <box size="0.03 0.045 0.35"/>
      </geometry>
    </collision>
  </link>
  <joint name="FL_thigh_joint" type="revolute">
    <origin xyz="0 0.134 0" rpy="0 0 0" />
    <parent link="FL_hip" />
    <child link="FL_thigh" />
    <axis xyz="0 1 0" />
    <limit lower="-0.69" upper="3" effort="200" velocity="5" />
  </joint>
  <link name="FL_calf">
    <inertial>
      <origin xyz="0.01596 0 -0.14872" rpy="0 0 0" />
      <mass value="1.0559" />
      <inertia ixx="0.01649" ixy="0" ixz="0.00146" iyy="0.01683" iyz="0" izz="0.00057" />
    </inertial>
    <visual>
      <origin xyz="0 0 0" rpy="0 0 0" />
      <geometry>
        <mesh filename="package://bruce_description/meshes/FL_calf.STL" />
      </geometry>
      <material name="">
        <color rgba="0.75294 0.75294 0.75294 1" />
      </material>
    </visual>
    <collision>
      <origin xyz="0.03 0 -0.15" rpy="0 -0.15 0" />
      <geometry>
        <box size="0.02 0.035 0.32"/>
      </geometry>
    </collision>
    <collision>
      <origin xyz="0 0 -0.12" rpy="0 -0.25 0" />
      <geometry>
        <box size="0.02 0.035 0.16"/>
      </geometry>
    </collision>
    <collision>
      <origin xyz="0 0 0" rpy="0 0 0" />
      <geometry>
        <box size="0.06 0.035 0.07"/>
      </geometry>
    </collision>
    <collision>
      <origin xyz="0.02 0 -0.25" rpy="0 0 0" />
      <geometry>
        <box size="0.02 0.035 0.08"/>
      </geometry>
    </collision>
    <collision>
      <origin xyz="0.02 0 -0.32" rpy="0 -0.8 0" />
      <geometry>
        <box size="0.02 0.035 0.06"/>
      </geometry>
    </collision>
  </link>
  <joint name="FL_calf_joint" type="revolute">
    <origin xyz="0 0 -0.325" rpy="0 0 0" />
    <parent link="FL_thigh" />
    <child link="FL_calf" />
    <axis xyz="0 1 0" />
    <limit lower="-2.7" upper="-0.80" effort="200" velocity="5" />
  </joint>
  <link name="FL_foot">
    <inertial>
      <origin xyz="-0.0044 0 -0.0045" rpy="0 0 0" />
      <mass value="0.20721" />
      <inertia ixx="0.00012" ixy="0" ixz="0.00003" iyy="0.00015" iyz="0" izz="0.00013" />
    </inertial>
    <visual>
      <origin xyz="0 0 0" rpy="0 0 0" />
      <geometry>
        <mesh filename="package://bruce_description/meshes/FL_foot.STL" />
      </geometry>
      <material name="">
        <color rgba="0.75294 0.75294 0.75294 1" />
      </material>
    </visual>
    <collision>
      <origin xyz="0.008 0 0.008" rpy="0 0 0" />
      <geometry> 
        <sphere radius="0.05" />
      </geometry>
    </collision>
  </link>
  <joint name="FL_foot_joint" type="fixed" dont_collapse="true">
    <origin xyz="1.9903E-05 0 -0.34532" rpy="0 0 0" />
    <parent link="FL_calf" />
    <child link="FL_foot" />
  </joint>

  <link name="FR_hip">
    <inertial>
      <origin xyz="-0.00576 0.01672 0" rpy="0 0 0" />
      <mass value="2.9" />
      <inertia ixx="0.00496" ixy="0.00034" ixz="0.00000" iyy="0.00840" iyz="0.00001" izz="0.00686" />
    </inertial>
    <visual>
      <origin xyz="0 0 0" rpy="0 0 0" />
      <geometry>
        <mesh filename="package://bruce_description/meshes/FR_hip.STL" />
      </geometry>
      <material name="">
        <color rgba="0.75294 0.75294 0.75294 1" />
      </material>
    </visual>
    <collision>
      <origin xyz="0 0.024 0" rpy="1.57 0 0" />
      <geometry>
        <cylinder radius="0.065" length="0.07 "/>
      </geometry>
    </collision>
  </link>
  <joint name="FR_hip_joint" type="revolute">
    <origin
      xyz="0.34075 -0.0975 0.088"
      rpy="0 0 0" />
    <parent link="base_link" />
    <child link="FR_hip" />
    <axis
      xyz="1 0 0" />
    <limit
      lower="-0.75"
      upper="0.75"
      effort="200"
      velocity="5" />
  </joint>
  <link name="FR_thigh">
    <inertial>
      <origin xyz="-0.00465 0.05050 -0.03161" rpy="0 0 0" />
      <mass value="5.58" />
      <inertia ixx="0.05229" ixy="-0.00049" ixz="0.00270" iyy="0.04971" iyz="-0.00720" izz="0.01637" />
    </inertial>
    <visual>
      <origin xyz="0 0 0" rpy="0 0 0" />
      <geometry>
        <mesh filename="package://bruce_description/meshes/FR_thigh.STL" />
      </geometry>
      <material name="">
        <color rgba="0.75294 0.75294 0.75294 1" />
      </material>
    </visual>
    <collision>
      <origin xyz="0 0.045 0" rpy="1.57 0 0" />
      <geometry>
        <cylinder radius="0.07" length="0.14 "/>
      </geometry>
    </collision>
    <collision>
      <origin xyz="-0.0 0 -0.12" rpy="0 0.3 0" />
      <geometry>
        <box size="0.065 0.045 0.22"/>
      </geometry>
    </collision>
    <collision>
      <origin xyz="-0.05 0 -0.12" rpy="0 0 0" />
      <geometry>
        <box size="0.03 0.045 0.35"/>
      </geometry>
    </collision>
  </link>
  <joint name="FR_thigh_joint" type="revolute">
    <origin xyz="0 -0.134 0" rpy="0 0 0" />
    <parent link="FR_hip" />
    <child link="FR_thigh" />
    <axis xyz="0 1 0" />
    <limit lower="-0.69" upper="3" effort="200" velocity="5" />
  </joint>
  <link name="FR_calf">
    <inertial>
      <origin xyz="0.01596 0 -0.14872" rpy="0 0 0" />
      <mass value="1.0559" />
      <inertia ixx="0.01649" ixy="0" ixz="0.00146" iyy="0.01683" iyz="0" izz="0.00057" />
    </inertial>
    <visual>
      <origin xyz="0 0 0" rpy="0 0 0" />
      <geometry>
        <mesh filename="package://bruce_description/meshes/FR_calf.STL" />
      </geometry>
      <material name="">
        <color rgba="0.75294 0.75294 0.75294 1" />
      </material>
    </visual>
    <collision>
      <origin xyz="0.03 0 -0.15" rpy="0 -0.15 0" />
      <geometry>
        <box size="0.02 0.035 0.32"/>
      </geometry>
    </collision>
    <collision>
      <origin xyz="0 0 -0.12" rpy="0 -0.25 0" />
      <geometry>
        <box size="0.02 0.035 0.16"/>
      </geometry>
    </collision>
    <collision>
      <origin xyz="0 0 0" rpy="0 0 0" />
      <geometry>
        <box size="0.06 0.035 0.07"/>
      </geometry>
    </collision>
    <collision>
      <origin xyz="0.02 0 -0.25" rpy="0 0 0" />
      <geometry>
        <box size="0.02 0.035 0.08"/>
      </geometry>
    </collision>
    <collision>
      <origin xyz="0.02 0 -0.32" rpy="0 -0.8 0" />
      <geometry>
        <box size="0.02 0.035 0.06"/>
      </geometry>
    </collision>
  </link>
  <joint name="FR_calf_joint" type="revolute">
    <origin xyz="0 0 -0.325" rpy="0 0 0" />
    <parent link="FR_thigh" />
    <child link="FR_calf" />
    <axis xyz="0 1 0" />
    <limit lower="-2.7" upper="-0.80" effort="200" velocity="5" />
  </joint>
  <link name="FR_foot">
    <inertial>
      <origin xyz="-0.0044 0 -0.0045" rpy="0 0 0" />
      <mass value="0.20721" />
      <inertia ixx="0.00012" ixy="0" ixz="0.00003" iyy="0.00015" iyz="0" izz="0.00013" />
    </inertial>
    <visual>
      <origin xyz="0 0 0" rpy="0 0 0" />
      <geometry>
        <mesh filename="package://bruce_description/meshes/FR_foot.STL" />
      </geometry>
      <material name="">
        <color rgba="0.75294 0.75294 0.75294 1" />
      </material>
    </visual>
    <collision>
      <origin xyz="0.008 0 0.008" rpy="0 0 0" />
      <geometry> 
        <sphere radius="0.05" />
      </geometry>
    </collision>
  </link>
  <joint name="FR_foot_joint" type="fixed" dont_collapse="true">
    <origin xyz="1.9903E-05 0 -0.34532" rpy="0 0 0" />
    <parent link="FR_calf" />
    <child link="FR_foot" />
  </joint>

  <link name="RL_hip">
    <inertial>
      <origin xyz="-0.00576 0.01672 0" rpy="0 0 0" />
      <mass value="2.9" />
      <inertia ixx="0.00496" ixy="0.00034" ixz="0.00000" iyy="0.00840" iyz="-0.00001" izz="0.00686" />
    </inertial>
    <visual>
      <origin xyz="0 0 0" rpy="0 0 0" />
      <geometry>
        <mesh filename="package://bruce_description/meshes/RL_hip.STL" />
      </geometry>
      <material name="">
        <color rgba="0.75294 0.75294 0.75294 1" />
      </material>
    </visual>
    <collision>
      <origin xyz="0 -0.024 0" rpy="1.57 0 0" />
      <geometry>
        <cylinder radius="0.065" length="0.07 "/>
      </geometry>
    </collision>
  </link>
  <joint name="RL_hip_joint" type="revolute">
    <origin xyz="-0.34075 0.0975 0.088" rpy="0 0 0" />
    <parent link="base_link" />
    <child link="RL_hip" />
    <axis xyz="1 0 0" />
    <limit lower="-0.75" upper="0.75" effort="200" velocity="5" />
  </joint>
  <link name="RL_thigh">
    <inertial>
      <origin xyz="-0.00465 -0.05050 -0.03161" rpy="0 0 0" />
      <mass value="5.58" />
      <inertia ixx="0.05229" ixy="0.00049" ixz="0.00270" iyy="0.04971" iyz="0.00720" izz="0.01637" />
    </inertial>
    <visual>
      <origin xyz="0 0 0" rpy="0 0 0" />
      <geometry>
        <mesh filename="package://bruce_description/meshes/RL_thigh.STL" />
      </geometry>
      <material name="">
        <color rgba="0.75294 0.75294 0.75294 1" />
      </material>
    </visual>
    <collision>
      <origin xyz="0 -0.045 0" rpy="1.57 0 0" />
      <geometry>
        <cylinder radius="0.07" length="0.14 "/>
      </geometry>
    </collision>
    <collision>
      <origin xyz="-0.0 0 -0.12" rpy="0 0.3 0" />
      <geometry>
        <box size="0.065 0.045 0.22"/>
      </geometry>
    </collision>
    <collision>
      <origin xyz="-0.05 0 -0.12" rpy="0 0 0" />
      <geometry>
        <box size="0.03 0.045 0.35"/>
      </geometry>
    </collision>
  </link>
  <joint name="RL_thigh_joint" type="revolute">
    <origin xyz="0 0.134 0" rpy="0 0 0" />
    <parent link="RL_hip" />
    <child link="RL_thigh" />
    <axis xyz="0 1 0" />
    <limit lower="-0.69" upper="3" effort="200" velocity="5" />
  </joint>
  <link name="RL_calf">
    <inertial>
      <origin xyz="0.01596 0 -0.14872" rpy="0 0 0" />
      <mass value="1.0559" />
      <inertia ixx="0.01649" ixy="0" ixz="0.00146" iyy="0.01683" iyz="0" izz="0.00057" />
    </inertial>
    <visual>
      <origin xyz="0 0 0" rpy="0 0 0" />
      <geometry>
        <mesh filename="package://bruce_description/meshes/RL_calf.STL" />
      </geometry>
      <material name="">
        <color rgba="0.75294 0.75294 0.75294 1" />
      </material>
    </visual>
    <collision>
      <origin xyz="0.03 0 -0.15" rpy="0 -0.15 0" />
      <geometry>
        <box size="0.02 0.035 0.32"/>
      </geometry>
    </collision>
    <collision>
      <origin xyz="0 0 -0.12" rpy="0 -0.25 0" />
      <geometry>
        <box size="0.02 0.035 0.16"/>
      </geometry>
    </collision>
    <collision>
      <origin xyz="0 0 0" rpy="0 0 0" />
      <geometry>
        <box size="0.06 0.035 0.07"/>
      </geometry>
    </collision>
    <collision>
      <origin xyz="0.02 0 -0.25" rpy="0 0 0" />
      <geometry>
        <box size="0.02 0.035 0.08"/>
      </geometry>
    </collision>
    <collision>
      <origin xyz="0.02 0 -0.32" rpy="0 -0.8 0" />
      <geometry>
        <box size="0.02 0.035 0.06"/>
      </geometry>
    </collision>
  </link>
  <joint name="RL_calf_joint" type="revolute">
    <origin xyz="0 0 -0.325" rpy="0 0 0" />
    <parent link="RL_thigh" />
    <child link="RL_calf" />
    <axis xyz="0 1 0" />
    <limit lower="-2.7" upper="-0.80" effort="200" velocity="5" />
  </joint>
  <link name="RL_foot">
    <inertial>
      <origin xyz="-0.0044 0 -0.0045" rpy="0 0 0" />
      <mass value="0.20721" />
      <inertia ixx="0.00012" ixy="0" ixz="0.00003" iyy="0.00015" iyz="0" izz="0.00013" />
    </inertial>
    <visual>
      <origin xyz="0 0 0" rpy="0 0 0" />
      <geometry>
        <mesh filename="package://bruce_description/meshes/RL_foot.STL" />
      </geometry>
      <material name="">
        <color rgba="0.75294 0.75294 0.75294 1" />
      </material>
    </visual>
    <collision>
      <origin xyz="0.008 0 0.008" rpy="0 0 0" />
      <geometry> 
        <sphere radius="0.05" />
      </geometry>
    </collision>
  </link>
  <joint name="RL_foot_joint" type="fixed" dont_collapse="true">
    <origin xyz="1.9903E-05 0 -0.34532" rpy="0 0 0" />
    <parent link="RL_calf" />
    <child link="RL_foot" />
  </joint>

  <link name="RR_hip">
    <inertial>
      <origin xyz="0.0058 0.0167 0" rpy="0 0 0" />
      <mass value="2.9" />
      <inertia
        ixx="0.0058"
        ixy="0"
        ixz="0"
        iyy="0.0085"
        iyz="0"
        izz="0.0079" />
    </inertial>
    <visual>
      <origin xyz="0 0 0" rpy="0 0 0" />
      <geometry>
        <mesh filename="package://bruce_description/meshes/RR_hip.STL" />
      </geometry>
      <material name="">
        <color rgba="0.75294 0.75294 0.75294 1" />
      </material>
    </visual>
    <collision>
      <origin xyz="0 0.024 0" rpy="1.57 0 0" />
      <geometry>
        <cylinder radius="0.065" length="0.07 "/>
      </geometry>
    </collision>
  </link>
  <joint name="RR_hip_joint" type="revolute">
    <origin xyz="-0.34075 -0.0975 0.088" rpy="0 0 0" /> 
    <parent link="base_link" />
    <child link="RR_hip" />
    <axis xyz="1 0 0" />
    <limit lower="-0.75" upper="0.75" effort="200" velocity="5" />
  </joint>
  <link name="RR_thigh">
    <inertial>
      <origin xyz="-0.00465 0.05050 -0.03161" rpy="0 0 0" />
      <mass value="5.58" />
      <inertia ixx="0.05229" ixy="-0.00049" ixz="0.00270" iyy="0.04971" iyz="-0.00720" izz="0.01637" />
    </inertial>
    <visual>
      <origin xyz="0 0 0" rpy="0 0 0" />
      <geometry>
        <mesh filename="package://bruce_description/meshes/RR_thigh.STL" />
      </geometry>
      <material name="">
        <color rgba="0.75294 0.75294 0.75294 1" />
      </material>
    </visual>
    <collision>
      <origin xyz="0 0.045 0" rpy="1.57 0 0" />
      <geometry>
        <cylinder radius="0.07" length="0.14 "/>
      </geometry>
    </collision>
    <collision>
      <origin xyz="-0.0 0 -0.12" rpy="0 0.3 0" />
      <geometry>
        <box size="0.065 0.045 0.22"/>
      </geometry>
    </collision>
    <collision>
      <origin xyz="-0.05 0 -0.12" rpy="0 0 0" />
      <geometry>
        <box size="0.03 0.045 0.35"/>
      </geometry>
    </collision>
  </link>
  <joint name="RR_thigh_joint" type="revolute">
    <origin xyz="0 -0.134 0" rpy="0 0 0" />
    <parent link="RR_hip" />
    <child link="RR_thigh" />
    <axis xyz="0 1 0" />
    <limit lower="-0.69" upper="3" effort="200" velocity="5" />
  </joint>
  <link name="RR_calf">
    <inertial>
      <origin xyz="0.01596 0 -0.14872" rpy="0 0 0" />
      <mass value="1.0559" />
      <inertia ixx="0.01649" ixy="0" ixz="0.00146" iyy="0.01683" iyz="0" izz="0.00057" />
    </inertial>
    <visual>
      <origin xyz="0 0 0" rpy="0 0 0" />
      <geometry>
        <mesh filename="package://bruce_description/meshes/RR_calf.STL" />
      </geometry>
      <material name="">
        <color rgba="0.75294 0.75294 0.75294 1" />
      </material>
    </visual>
    <collision>
      <origin xyz="0.03 0 -0.15" rpy="0 -0.15 0" />
      <geometry>
        <box size="0.02 0.035 0.32"/>
      </geometry>
    </collision>
    <collision>
      <origin xyz="0 0 -0.12" rpy="0 -0.25 0" />
      <geometry>
        <box size="0.02 0.035 0.16"/>
      </geometry>
    </collision>
    <collision>
      <origin xyz="0 0 0" rpy="0 0 0" />
      <geometry>
        <box size="0.06 0.035 0.07"/>
      </geometry>
    </collision>
    <collision>
      <origin xyz="0.02 0 -0.25" rpy="0 0 0" />
      <geometry>
        <box size="0.02 0.035 0.08"/>
      </geometry>
    </collision>
    <collision>
      <origin xyz="0.02 0 -0.32" rpy="0 -0.8 0" />
      <geometry>
        <box size="0.02 0.035 0.06"/>
      </geometry>
    </collision>
  </link>
  <joint name="RR_calf_joint" type="revolute">
    <origin xyz="0 0 -0.325" rpy="0 0 0" />
    <parent link="RR_thigh" />
    <child link="RR_calf" />
    <axis xyz="0 1 0" />
    <limit lower="-2.7" upper="-0.80" effort="200" velocity="5" />
  </joint>
  <link name="RR_foot">
    <inertial>
      <origin xyz="-0.0044 0 -0.0045" rpy="0 0 0" />
      <mass value="0.20721" />
      <inertia ixx="0.00012" ixy="0" ixz="0.00003" iyy="0.00015" iyz="0" izz="0.00013" />
    </inertial>
    <visual>
      <origin xyz="0 0 0" rpy="0 0 0" />
      <geometry>
        <mesh filename="package://bruce_description/meshes/RR_foot.STL" />
      </geometry>
      <material name="">
        <color rgba="0.75294 0.75294 0.75294 1" />
      </material>
    </visual>
    <collision>
      <origin xyz="0.008 0 0.008" rpy="0 0 0" />
      <geometry> 
        <sphere radius="0.05" />
      </geometry>
    </collision>
  </link>
  <joint name="RR_foot_joint" type="fixed" dont_collapse="true">
    <origin xyz="1.9903E-05 0 -0.34532" rpy="0 0 0" />
    <parent link="RR_calf" />
    <child link="RR_foot" />
  </joint>

  <link name="imu_link">
    <inertial>
      <origin xyz="0 0 0" rpy="0 0 0" />
      <mass value="0" />
      <inertia ixx="0" ixy="0" ixz="0" iyy="0" iyz="0" izz="0" />
    </inertial>
  </link>
  <joint name="imu_joint" type="fixed">
    <origin xyz="0 0 0.114" rpy="0 0 0" />
    <parent link="base_link" />
    <child link="imu_link" />
    <axis xyz="0 0 0" />
  </joint>

</robot>